<robot name="faller"><link name="chassis"><visual><geometry><box size="0.254 0.1651 0.05" /></geometry><material name="white"><color rgba="1.0 1.0 1.0 1.0" /></material></visual><collision><geometry><box size="0.254 0.1651 0.05" /></geometry></collision><inertial><mass value="0.7" /><inertia ixx="0.00173588391667" iyy="0.00390926666667" izz="0.00535348391667" /></inertial></link><link name="front_left_wheel"><visual><geometry><cylinder length="0.02" radius="0.051" /></geometry><material name="white"><color rgba="1.0 1.0 1.0 1.0" /></material><origin rpy="1.57079632679 0 0" xyz="0 0 0" /></visual><collision><geometry><cylinder length="0.02" radius="0.051" /></geometry><origin rpy="1.57079632679 0 0" xyz="0 0 0" /></collision><inertial><mass value="0.102" /><inertia ixx="6.97255e-05" iyy="6.97255e-05" izz="0.000132651" /></inertial></link><joint name="front_left_link" type="continuous"><parent link="chassis" /><child link="front_left_wheel" /><axis xyz="0 1 1" /><origin xyz="0.1015 0.09255 0" /></joint><link name="front_right_wheel"><visual><geometry><cylinder length="0.02" radius="0.051" /></geometry><material name="white"><color rgba="1.0 1.0 1.0 1.0" /></material><origin rpy="1.57079632679 0 0" xyz="0 0 0" /></visual><collision><geometry><cylinder length="0.02" radius="0.051" /></geometry><origin rpy="1.57079632679 0 0" xyz="0 0 0" /></collision><inertial><mass value="0.102" /><inertia ixx="6.97255e-05" iyy="6.97255e-05" izz="0.000132651" /></inertial></link><joint name="front_right_link" type="continuous"><parent link="chassis" /><child link="front_right_wheel" /><axis xyz="0 1 0" /><origin xyz="0.1015 -0.09255 0" /></joint><link name="back_left_wheel"><visual><geometry><cylinder length="0.02" radius="0.051" /></geometry><material name="white"><color rgba="1.0 1.0 1.0 1.0" /></material><origin rpy="0.785398163397 0 0" xyz="0 0 0" /></visual><collision><geometry><cylinder length="0.02" radius="0.051" /></geometry><origin rpy="0.785398163397 0 0" xyz="0 0 0" /></collision><inertial><mass value="0.102" /><inertia ixx="6.97255e-05" iyy="6.97255e-05" izz="0.000132651" /></inertial></link><joint name="back_left_link" type="continuous"><parent link="chassis" /><child link="back_left_wheel" /><axis xyz="0 1 -1" /><origin xyz="-0.1015 0.09255 0" /></joint><link name="back_right_wheel"><visual><geometry><cylinder length="0.02" radius="0.051" /></geometry><material name="white"><color rgba="1.0 1.0 1.0 1.0" /></material><origin rpy="-0.785398163397 0 0" xyz="0 0 0" /></visual><collision><geometry><cylinder length="0.02" radius="0.051" /></geometry><origin rpy="-0.785398163397 0 0" xyz="0 0 0" /></collision><inertial><mass value="0.102" /><inertia ixx="6.97255e-05" iyy="6.97255e-05" izz="0.000132651" /></inertial></link><joint name="back_right_link" type="continuous"><parent link="chassis" /><child link="back_right_wheel" /><axis xyz="0 1 1" /><origin xyz="-0.1015 -0.09255 0" /></joint></robot>