<?xml version="1.0"?>
<robot name="faller">
  <link name="chassis">
    <visual>
      <geometry>
        <box size="0.1905 0.1397 0.0254"/>
      </geometry>
      <material name="clear">
        <color rgba="1.0 1.0 1.0 0.2"/>
      </material>
    </visual>
    <collision>
      <geometry>
        <box size="0.1905 0.1397 0.0254"/>
      </geometry>
    </collision>
  </link>
  <link name="front_left_wheel">
    <visual>
      <geometry>
        <cylinder radius="0.025" length="0.02"/>
      </geometry>
      <origin rpy="1.57075 0 0" xyz="0.09525 0.06985 0"/>
    </visual>
    <collision>
      <geometry>
        <cylinder radius="0.025" length="0.02"/>
      </geometry>
      <origin rpy="1.57075 0 0" xyz="0.09525 0.06985 0"/>
    </collision>
  </link>
  <link name="front_right_wheel">
    <visual>
      <geometry>
        <cylinder radius="0.025" length="0.02"/>
      </geometry>
      <origin rpy="1.57075 0 0" xyz="0.09525 -0.06985 0"/>
    </visual>
    <collision>
      <geometry>
        <cylinder radius="0.025" length="0.02"/>
      </geometry>
      <origin rpy="1.57075 0 0" xyz="0.09525 -0.06985 0"/>
    </collision>
  </link>
  <link name="back_left_wheel">
    <visual>
      <geometry>
        <cylinder radius="0.025" length="0.02"/>
      </geometry>
      <origin rpy="1.57075 0 0" xyz="-0.09525 0.06985 0"/>
    </visual>
    <collision>
      <geometry>
        <cylinder radius="0.025" length="0.02"/>
      </geometry>
      <origin rpy="1.57075 0 0" xyz="-0.09525 0.06985 0"/>
    </collision>
  </link>
  <link name="back_right_wheel">
    <visual>
      <geometry>
        <cylinder radius="0.025" length="0.02"/>
      </geometry>
      <origin rpy="1.57075 0 0" xyz="-0.09525 -0.06985 0"/>
    </visual>
    <collision>
      <geometry>
        <cylinder radius="0.025" length="0.02"/>
      </geometry>
      <origin rpy="1.57075 0 0" xyz="-0.09525 -0.06985 0"/>
    </collision>
  </link>
  <joint name="front_left_link" type="continuous">
    <parent link="chassis"/>
    <child link="front_left_wheel"/>
    <axis xyz="0 1 0"/>
    <origin xyz="0 0 0"/>
  </joint>
  <joint name="front_right_link" type="continuous">
    <parent link="chassis"/>
    <child link="front_right_wheel"/>
    <axis xyz="0 1 0"/>
    <origin xyz="0 0 0"/>
  </joint>
  <joint name="back_left_link" type="continuous">
    <parent link="chassis"/>
    <child link="back_left_wheel"/>
    <axis xyz="0 1 0"/>
    <origin xyz="0 0 0"/>
  </joint>
  <joint name="back_right_link" type="continuous">
    <parent link="chassis"/>
    <child link="back_right_wheel"/>
    <axis xyz="0 1 0"/>
    <origin xyz="0 0 0"/>
  </joint>
</robot>
